<?xml version="1.0"?>
<robot name="alpha_5" xmlns:xacro="http://ros.org/wiki/xacro">
    <xacro:macro name="alpha_5" params="parent *origin name:=alpha_5 camera:=zedm">


        <joint name="${name}_joint" type="fixed">
            <xacro:insert_block name="origin" />
            <parent link="${parent}"/>
            <child link="${name}_base_link" />
        </joint>
        <material name="alpha_black">
            <color rgba="0.3 0.3 0.3 1"/>
        </material>
        <link name="${name}_base_link"/>
        <link name="${name}_m3_inline_link">
            <inertial>
                <origin xyz="-75e-3 -6e-3 -3e-3" rpy="0 0 0"/>
                <mass value="0.341"/>
                <inertia ixx="99e-6"  ixy="139e-6"  ixz="115e-6" iyy="2920e-6" iyz="3e-6" izz="2934e-6" />
            </inertial>
            <visual>
                <geometry>
                    <mesh filename="package://sim_alpha_description/meshes/M3-INLINE.stl"/>
                </geometry>
                <origin rpy="0 0 0" xyz="0 0 0"/>
                <material name="alpha_black"/>
            </visual>
            <collision>
                <geometry>
                    <cylinder length="0.150" radius="0.020" />
                </geometry>
                <origin rpy="0 1.57075 0" xyz="-0.075 0 0" />
            </collision>

        </link>
        <joint name="${name}_base_link_joint" type="fixed">
            <parent link="${name}_base_link"/>
            <child link="${name}_m3_inline_link"/>
            <origin rpy="0 0 0"/>
        </joint>
        <link name="${name}_m2_1_1_link">
            <inertial>
                <origin xyz="-5e-3 -1e-3 16e-3" rpy="0 0 0"/>
                <mass value="0.194"/>
                <inertia ixx="189e-6"  ixy="5e-6"  ixz="54e-6" iyy="213e-6" iyz="3e-6" izz="67e-6" />
            </inertial>        
            <visual>
                <geometry>
                    <mesh filename="package://sim_alpha_description/meshes/M2-1-1.stl"/>
                </geometry>
                <origin rpy="0 0 0" xyz="0 0 0"/>
                <material name="${name}_black"/>
            </visual>
            <collision>
                <geometry>
                    <cylinder length="0.066" radius="0.020" />
                </geometry>
                <origin rpy="0 0 0" xyz="0 0 0.000" />
            </collision>
        </link>


        <joint name="${name}_axis_e" type="revolute">
            <parent link="${name}_m3_inline_link"/>
            <child link="${name}_m2_1_1_link"/>
            <origin xyz="0 0 0.014"/>
            <axis xyz="0 0 1"/>
            <limit effort="9.0" lower="0.0" upper="6.3" velocity="0.5"/>
        </joint>
        <link name="${name}_m2_joint_link">
            <inertial>
                <origin xyz="0 0 0" rpy="0 0 0"/>
                <mass value="0.429"/>
                <inertia ixx="87e-6"  ixy="-76e-6"  ixz="-10e-6" iyy="3190e-6" iyz="0" izz="3213e-6" />
            </inertial>        
            <visual>
                <geometry>
                    <mesh filename="package://sim_alpha_description/meshes/M2.stl"/>
                </geometry>
                <origin rpy="0 0 0" xyz="0 0 0"/>
                <material name="${name}_black"/>
            </visual>
            <collision>
                <geometry>
                    <cylinder length="0.145" radius="0.020" />
                </geometry>
                <origin rpy="0 0 0" xyz="-0.02 0 -0.0725" />
            </collision>
            <collision>
                <geometry>
                    <cylinder length="0.040" radius="0.020" />
                </geometry>
                <origin rpy="1.5707 0 0" xyz="0 0 0" />
            </collision>

            <collision>
                <geometry>
                    <cylinder length="0.040" radius="0.020" />
                </geometry>
                <origin rpy="1.5707 0 0" xyz="-0.040 0 -0.1453" />
            </collision>
        </link>


        <joint name="${name}_axis_d" type="revolute">
            <parent link="${name}_m2_1_1_link"/>
            <child link="${name}_m2_joint_link"/>
            <origin xyz="-0.02 0 0.033"/>
            <axis xyz="0 1 0"/>
            <limit effort="9.0" lower="0.0" upper="3.8" velocity="0.5"/>
        </joint>
        <link name="${name}_m2_1_2_link">
            <inertial>
                <origin xyz="17e-3 -26e-3 -2e-3" rpy="0 0 0"/>
                <mass value="0.115"/>
                <inertia ixx="120e-6"  ixy="-61e-6"  ixz="-1e-6" iyy="62e-6" iyz="0" izz="156e-6" />
            </inertial>        
            <visual>
                <geometry>
                    <mesh filename="package://sim_alpha_description/meshes/M2-1-3.stl"/>
                </geometry>
                <origin rpy="0 0 0" xyz="0 0 0"/>
                <material name="${name}_black"/>
            </visual>

            <collision>
                <geometry>
                    <cylinder length="0.033" radius="0.020" />
                </geometry>
                <origin rpy="0 0 0" xyz="0.02 0 0.0165" />
            </collision>
        </link>


        <joint name="${name}_axis_c" type="revolute">
            <parent link="${name}_m2_joint_link"/>
            <child link="${name}_m2_1_2_link"/>
            <origin xyz="-0.04 0 -0.1453" rpy="0 0 3.14159"/>
            <axis xyz="0 1 0"/>
            <limit effort="9.0" lower="0.0" upper="3.5" velocity="0.5"/>
        </joint>
        <link name="${name}_m1_link">
            <inertial>
                <origin xyz="0e-3 3e-3 -98e-3" rpy="0 0 0"/>
                <mass value="0.333"/>
                <inertia ixx="3709e-6"  ixy="2e-6"  ixz="-4e-6" iyy="3734e-6" iyz="0" izz="79e-6" />
            </inertial>
            <visual>
                <geometry>
                    <mesh filename="package://sim_alpha_description/meshes/RS1-100-101-123.stl"/>
                </geometry>
                <origin rpy="0 -1.5707 0" xyz="0 0 0"/>
                <material name="${name}_black"/>
            </visual>

            <collision>
                <geometry>
                    <cylinder length="0.10975" radius="0.020" />
                </geometry>
                <origin rpy="0 0 0" xyz="0.00 0 0.054875" />
            </collision>
        </link>
        <joint name="${name}_axis_b" type="revolute">
            <parent link="${name}_m2_1_2_link"/>
            <child link="${name}_m1_link"/>
            <origin xyz="0.02 0 0.033" rpy="0 0 2.09439"/>
            <axis xyz="0 0 -1"/>
            <limit effort="9.0" lower="0.0" upper="6.2" velocity="0.5"/>
        </joint>
        <material name="${name}_jaws_black">
            <color rgba="0.3 0.3 0.3 1"/>
        </material>
        <joint name="${name}_jaws_joint" type="fixed">
            <origin rpy="0 0 0" xyz="0 0 0.09975"/>
            <parent link="${name}_m1_link"/>
            <child link="${name}_jaws_base_link"/>
        </joint>
        <link name="${name}_jaws_base_link">


        </link>
        <link name="${name}_push_rod"/>
        <joint name="${name}_axis_a" type="fixed">
            <origin rpy="0 0 0" xyz="0 0 0.009"/>
            <parent link="${name}_jaws_base_link"/>
            <child link="${name}_push_rod"/>
        </joint>

        <xacro:include filename="$(find sim_alpha_description)/urdf/end_effectors/standard_jaws.urdf.xacro"/>
        <xacro:alpha_standard_jaws parent="${name}_jaws_base_link" name="${name}_standard_jaws" axis_a="${name}_axis_a">
            <origin xyz="0 0 0" rpy="0 0 0"/>
        </xacro:alpha_standard_jaws>
     
        <xacro:include filename="$(find zed_wrapper)/urdf/zed_macro.urdf.xacro" />
        <xacro:zed_camera  parent="${name}_jaws_base_link" name="${camera}" model="${camera}">
            <origin xyz="0 0.015 0.09" rpy="${pi/2} ${-pi/2} 0"/>
        </xacro:zed_camera>




    </xacro:macro>
</robot>